Traceback (most recent call last):
  File "exploreByNext.py", line 55, in <module>
    length=lib.getDuration(currentVideoId)
  File "D:\Benny\università\Tesi\lib.py", line 67, in getDuration
    api_service_name, api_version, developerKey=yt_api_key)
  File "C:\Users\Benny\anaconda3\lib\site-packages\googleapiclient\_helpers.py", line 134, in positional_wrapper
    return wrapped(*args, **kwargs)
  File "C:\Users\Benny\anaconda3\lib\site-packages\googleapiclient\discovery.py", line 295, in build
    raise e
  File "C:\Users\Benny\anaconda3\lib\site-packages\googleapiclient\discovery.py", line 276, in build
    num_retries=num_retries,
  File "C:\Users\Benny\anaconda3\lib\site-packages\googleapiclient\discovery.py", line 376, in _retrieve_discovery_doc
    resp, content = req.execute(num_retries=num_retries)
  File "C:\Users\Benny\anaconda3\lib\site-packages\googleapiclient\_helpers.py", line 134, in positional_wrapper
    return wrapped(*args, **kwargs)
  File "C:\Users\Benny\anaconda3\lib\site-packages\googleapiclient\http.py", line 907, in execute
    raise HttpError(resp, content, uri=self.uri)
googleapiclient.errors.HttpError: <HttpError 400 when requesting https://www.googleapis.com/discovery/v1/apis/youtube/v3/rest?key=Insert+here+your+api_key returned "API key not valid. Please pass a valid API key.". Details: "[{'@type': 'type.googleapis.com/google.rpc.ErrorInfo', 'reason': 'API_KEY_INVALID', 'domain': 'googleapis.com', 'metadata': {'service': 'youtube.googleapis.com'}}]">
